<?xml version="1.0"?>
<robot name="screws">

    <link name="box">
        <visual>
            <geometry>
                <box size="1 1 1"/>  <!-- 1x1x1 meter box, extending from 0 to 1 in Z -->  <!-- 1x1x1 meter box -->
            </geometry>
            <material name="transparent_gray">
                <color rgba="0.5 0.5 0.5 0.5"/>
            </material>
        </visual>
        <collision>
            <geometry>
                <box size="1 1 1"/>
            </geometry>
        </collision>
        <inertial>
            <mass value="1.0"/>
            <inertia ixx="0.1" iyy="0.1" izz="0.1" ixy="0" ixz="0" iyz="0"/>
        </inertial>
    </link>

    <!-- Screw Link (Revolute on Box) -->
    <link name="screw_torx_T30">
        <visual>
            <geometry>
                <cylinder length="0.3" radius="0.025"/>  <!-- Approximate screw dimensions -->
            </geometry>
            <material name="blue">
                <color rgba="0 0 1 1"/>
            </material>
        </visual>
        <collision>
            <geometry>
                <cylinder length="0.3" radius="0.025"/>
            </geometry>
        </collision>
        <inertial>
            <mass value="0.002"/>
            <inertia ixx="1e-6" iyy="1e-6" izz="1e-6" ixy="0" ixz="0" iyz="0"/>
        </inertial>
    </link>

    <!-- Revolute Joint to Attach the Screw to the Box -->
    <joint name="screw_joint" type="revolute">
        <parent link="box"/>
        <child link="screw_torx_T30"/>
        <origin xyz="0 0 0.35" rpy="0 0 0"/>  <!-- Positioned above the box -->
        <axis xyz="0 0 1"/>
        <limit effort="1.0" velocity="1.0" lower="-3.14" upper="3.14"/>
    </joint>
    <!-- Gazebo-Specific Extensions -->

    <gazebo reference="box">
        <material>Gazebo/TransparentGray</material> 
    </gazebo>
    <gazebo reference="screw_torx_T30">
        <material>Gazebo/Red</material>
    </gazebo>
</robot>